Traceback (most recent call last):
  File "/Users/hanklee/.pyenv/versions/3.8.0/lib/python3.8/site-packages/jupyter_cache/executors/utils.py", line 51, in single_nb_execution
    executenb(
  File "/Users/hanklee/.pyenv/versions/3.8.0/lib/python3.8/site-packages/nbclient/client.py", line 1082, in execute
    return NotebookClient(nb=nb, resources=resources, km=km, **kwargs).execute()
  File "/Users/hanklee/.pyenv/versions/3.8.0/lib/python3.8/site-packages/nbclient/util.py", line 74, in wrapped
    return just_run(coro(*args, **kwargs))
  File "/Users/hanklee/.pyenv/versions/3.8.0/lib/python3.8/site-packages/nbclient/util.py", line 53, in just_run
    return loop.run_until_complete(coro)
  File "/Users/hanklee/.pyenv/versions/3.8.0/lib/python3.8/asyncio/base_events.py", line 608, in run_until_complete
    return future.result()
  File "/Users/hanklee/.pyenv/versions/3.8.0/lib/python3.8/site-packages/nbclient/client.py", line 535, in async_execute
    await self.async_execute_cell(
  File "/Users/hanklee/.pyenv/versions/3.8.0/lib/python3.8/site-packages/nbclient/client.py", line 827, in async_execute_cell
    self._check_raise_for_error(cell, exec_reply)
  File "/Users/hanklee/.pyenv/versions/3.8.0/lib/python3.8/site-packages/nbclient/client.py", line 735, in _check_raise_for_error
    raise CellExecutionError.from_cell_and_msg(cell, exec_reply['content'])
nbclient.exceptions.CellExecutionError: An error occurred while executing the following cell:
------------------
from sklearn.gaussian_process import GaussianProcess

# define the model and draw some data
model = lambda x: x * np.sin(x)
xdata = np.array([1, 3, 5, 6, 8])
ydata = model(xdata)

# Compute the Gaussian process fit
gp = GaussianProcess(corr='cubic', theta0=1e-2, thetaL=1e-4, thetaU=1E-1,
                     random_start=100)
gp.fit(xdata[:, np.newaxis], ydata)

xfit = np.linspace(0, 10, 1000)
yfit, MSE = gp.predict(xfit[:, np.newaxis], eval_MSE=True)
dyfit = 2 * np.sqrt(MSE)  # 2*sigma ~ 95% confidence region
------------------

[0;31m---------------------------------------------------------------------------[0m
[0;31mImportError[0m                               Traceback (most recent call last)
[0;32m<ipython-input-4-0aeb76e3f6ca>[0m in [0;36m<module>[0;34m[0m
[0;32m----> 1[0;31m [0;32mfrom[0m [0msklearn[0m[0;34m.[0m[0mgaussian_process[0m [0;32mimport[0m [0mGaussianProcess[0m[0;34m[0m[0;34m[0m[0m
[0m[1;32m      2[0m [0;34m[0m[0m
[1;32m      3[0m [0;31m# define the model and draw some data[0m[0;34m[0m[0;34m[0m[0;34m[0m[0m
[1;32m      4[0m [0mmodel[0m [0;34m=[0m [0;32mlambda[0m [0mx[0m[0;34m:[0m [0mx[0m [0;34m*[0m [0mnp[0m[0;34m.[0m[0msin[0m[0;34m([0m[0mx[0m[0;34m)[0m[0;34m[0m[0;34m[0m[0m
[1;32m      5[0m [0mxdata[0m [0;34m=[0m [0mnp[0m[0;34m.[0m[0marray[0m[0;34m([0m[0;34m[[0m[0;36m1[0m[0;34m,[0m [0;36m3[0m[0;34m,[0m [0;36m5[0m[0;34m,[0m [0;36m6[0m[0;34m,[0m [0;36m8[0m[0;34m][0m[0;34m)[0m[0;34m[0m[0;34m[0m[0m

[0;31mImportError[0m: cannot import name 'GaussianProcess' from 'sklearn.gaussian_process' (/Users/hanklee/.pyenv/versions/3.8.0/lib/python3.8/site-packages/sklearn/gaussian_process/__init__.py)
ImportError: cannot import name 'GaussianProcess' from 'sklearn.gaussian_process' (/Users/hanklee/.pyenv/versions/3.8.0/lib/python3.8/site-packages/sklearn/gaussian_process/__init__.py)

